<sdf version='1.10'>
    <model name='robotis_op3'>
        <plugin name='gz::sim::systems::Imu' filename='gz-sim-imu-system' />
        <plugin filename="gz-sim-joint-state-publisher-system"
            name="gz::sim::systems::JointStatePublisher">
            <topic>gazebo/joint_state</topic>
            <joint_name>l_hip_yaw</joint_name>
            <joint_name>l_hip_roll</joint_name>
            <joint_name>l_hip_pitch</joint_name>
            <joint_name>l_knee</joint_name>
            <joint_name>l_ank_roll</joint_name>
            <joint_name>l_ank_pitch</joint_name>
            <joint_name>r_hip_yaw</joint_name>
            <joint_name>r_hip_roll</joint_name>
            <joint_name>r_hip_pitch</joint_name>
            <joint_name>r_knee</joint_name>
            <joint_name>r_ank_roll</joint_name>
            <joint_name>r_ank_pitch</joint_name>
            <joint_name>l_sho_pitch</joint_name>
            <joint_name>l_sho_roll</joint_name>
            <joint_name>l_el</joint_name>
            <joint_name>r_sho_pitch</joint_name>
            <joint_name>r_sho_roll</joint_name>
            <joint_name>r_el</joint_name>
            <joint_name>head_pan</joint_name>
            <joint_name>head_tilt</joint_name>
        </plugin>
        <plugin filename="gz-sim-joint-position-controller-system"
            name="gz::sim::systems::JointPositionController">
            <joint_name>l_hip_yaw</joint_name>
            <p_gain>1</p_gain>
            <i_gain>0.1</i_gain>
            <d_gain>0.01</d_gain>
            <i_max>1</i_max>
            <i_min>-1</i_min>
            <cmd_max>1000</cmd_max>
            <cmd_min>-1000</cmd_min>
        </plugin>

        <plugin filename="gz-sim-joint-position-controller-system"
            name="gz::sim::systems::JointPositionController">
            <joint_name>l_hip_roll</joint_name>
            <p_gain>1</p_gain>
            <i_gain>0.1</i_gain>
            <d_gain>0.01</d_gain>
            <i_max>1</i_max>
            <i_min>-1</i_min>
            <cmd_max>1000</cmd_max>
            <cmd_min>-1000</cmd_min>
        </plugin>

        <plugin filename="gz-sim-joint-position-controller-system"
            name="gz::sim::systems::JointPositionController">
            <joint_name>l_hip_pitch</joint_name>
            <p_gain>1</p_gain>
            <i_gain>0.1</i_gain>
            <d_gain>0.01</d_gain>
            <i_max>1</i_max>
            <i_min>-1</i_min>
            <cmd_max>1000</cmd_max>
            <cmd_min>-1000</cmd_min>

        </plugin>
        <plugin filename="gz-sim-joint-position-controller-system"
            name="gz::sim::systems::JointPositionController">
            <joint_name>l_knee</joint_name>
            <p_gain>1</p_gain>
            <i_gain>0.1</i_gain>
            <d_gain>0.01</d_gain>
            <i_max>1</i_max>
            <i_min>-1</i_min>
            <cmd_max>1000</cmd_max>
            <cmd_min>-1000</cmd_min>
        </plugin>
        <plugin filename="gz-sim-joint-position-controller-system"
            name="gz::sim::systems::JointPositionController">
            <joint_name>l_ank_roll</joint_name>
            <p_gain>1</p_gain>
            <i_gain>0.1</i_gain>
            <d_gain>0.01</d_gain>
            <i_max>1</i_max>
            <i_min>-1</i_min>
            <cmd_max>1000</cmd_max>
            <cmd_min>-1000</cmd_min>
        </plugin>
        <plugin filename="gz-sim-joint-position-controller-system"
            name="gz::sim::systems::JointPositionController">
            <joint_name>l_ank_pitch</joint_name>
            <p_gain>1</p_gain>
            <i_gain>0.1</i_gain>
            <d_gain>0.01</d_gain>
            <i_max>1</i_max>
            <i_min>-1</i_min>
            <cmd_max>1000</cmd_max>
            <cmd_min>-1000</cmd_min>
        </plugin>
        <plugin filename="gz-sim-joint-position-controller-system"
            name="gz::sim::systems::JointPositionController">
            <joint_name>r_hip_yaw</joint_name>
            <p_gain>1</p_gain>
            <i_gain>0.1</i_gain>
            <d_gain>0.01</d_gain>
            <i_max>1</i_max>
            <i_min>-1</i_min>
            <cmd_max>1000</cmd_max>
            <cmd_min>-1000</cmd_min>
        </plugin>
        <plugin filename="gz-sim-joint-position-controller-system"
            name="gz::sim::systems::JointPositionController">
            <joint_name>r_hip_roll</joint_name>
            <p_gain>1</p_gain>
            <i_gain>0.1</i_gain>
            <d_gain>0.01</d_gain>
            <i_max>1</i_max>
            <i_min>-1</i_min>
            <cmd_max>1000</cmd_max>
            <cmd_min>-1000</cmd_min>
        </plugin>
        <plugin filename="gz-sim-joint-position-controller-system"
            name="gz::sim::systems::JointPositionController">
            <joint_name>r_hip_pitch</joint_name>
            <p_gain>1</p_gain>
            <i_gain>0.1</i_gain>
            <d_gain>0.01</d_gain>
            <i_max>1</i_max>
            <i_min>-1</i_min>
            <cmd_max>1000</cmd_max>
            <cmd_min>-1000</cmd_min>
        </plugin>
        <plugin filename="gz-sim-joint-position-controller-system"
            name="gz::sim::systems::JointPositionController">
            <joint_name>r_knee</joint_name>
            <p_gain>1</p_gain>
            <i_gain>0.1</i_gain>
            <d_gain>0.01</d_gain>
            <i_max>1</i_max>
            <i_min>-1</i_min>
            <cmd_max>1000</cmd_max>
            <cmd_min>-1000</cmd_min>
        </plugin>
        <plugin filename="gz-sim-joint-position-controller-system"
            name="gz::sim::systems::JointPositionController">
            <joint_name>r_ank_roll</joint_name>
            <p_gain>1</p_gain>
            <i_gain>0.1</i_gain>
            <d_gain>0.01</d_gain>
            <i_max>1</i_max>
            <i_min>-1</i_min>
            <cmd_max>1000</cmd_max>
            <cmd_min>-1000</cmd_min>
        </plugin>
        <plugin filename="gz-sim-joint-position-controller-system"
            name="gz::sim::systems::JointPositionController">
            <joint_name>r_ank_pitch</joint_name>
            <p_gain>1</p_gain>
            <i_gain>0.1</i_gain>
            <d_gain>0.01</d_gain>
            <i_max>1</i_max>
            <i_min>-1</i_min>
            <cmd_max>1000</cmd_max>
            <cmd_min>-1000</cmd_min>
        </plugin>
        <plugin filename="gz-sim-joint-position-controller-system"
            name="gz::sim::systems::JointPositionController">
            <joint_name>l_sho_pitch</joint_name>
            <p_gain>1</p_gain>
            <i_gain>0.1</i_gain>
            <d_gain>0.01</d_gain>
            <i_max>1</i_max>
            <i_min>-1</i_min>
            <cmd_max>1000</cmd_max>
            <cmd_min>-1000</cmd_min>
        </plugin>
        <plugin filename="gz-sim-joint-position-controller-system"
            name="gz::sim::systems::JointPositionController">
            <joint_name>l_sho_roll</joint_name>
            <p_gain>1</p_gain>
            <i_gain>0.1</i_gain>
            <d_gain>0.01</d_gain>
            <i_max>1</i_max>
            <i_min>-1</i_min>
            <cmd_max>1000</cmd_max>
            <cmd_min>-1000</cmd_min>
        </plugin>
        <plugin filename="gz-sim-joint-position-controller-system"
            name="gz::sim::systems::JointPositionController">
            <joint_name>l_el</joint_name>
            <p_gain>1</p_gain>
            <i_gain>0.1</i_gain>
            <d_gain>0.01</d_gain>
            <i_max>1</i_max>
            <i_min>-1</i_min>
            <cmd_max>1000</cmd_max>
            <cmd_min>-1000</cmd_min>
        </plugin>
        <plugin filename="gz-sim-joint-position-controller-system"
            name="gz::sim::systems::JointPositionController">
            <joint_name>r_sho_pitch</joint_name>
            <p_gain>1</p_gain>
            <i_gain>0.1</i_gain>
            <d_gain>0.01</d_gain>
            <i_max>1</i_max>
            <i_min>-1</i_min>
            <cmd_max>1000</cmd_max>
            <cmd_min>-1000</cmd_min>
        </plugin>
        <plugin filename="gz-sim-joint-position-controller-system"
            name="gz::sim::systems::JointPositionController">
            <joint_name>r_sho_roll</joint_name>
            <p_gain>1</p_gain>
            <i_gain>0.1</i_gain>
            <d_gain>0.01</d_gain>
            <i_max>1</i_max>
            <i_min>-1</i_min>
            <cmd_max>1000</cmd_max>
            <cmd_min>-1000</cmd_min>
        </plugin>
        <plugin filename="gz-sim-joint-position-controller-system"
            name="gz::sim::systems::JointPositionController">
            <joint_name>r_el</joint_name>
            <p_gain>1</p_gain>
            <i_gain>0.1</i_gain>
            <d_gain>0.01</d_gain>
            <i_max>1</i_max>
            <i_min>-1</i_min>
            <cmd_max>1000</cmd_max>
            <cmd_min>-1000</cmd_min>
        </plugin>
        <plugin filename="gz-sim-joint-position-controller-system"
            name="gz::sim::systems::JointPositionController">
            <joint_name>head_pan</joint_name>
            <p_gain>1</p_gain>
            <i_gain>0.1</i_gain>
            <d_gain>0.01</d_gain>
            <i_max>1</i_max>
            <i_min>-1</i_min>
            <cmd_max>1000</cmd_max>
            <cmd_min>-1000</cmd_min>
        </plugin>
        <plugin filename="gz-sim-joint-position-controller-system"
            name="gz::sim::systems::JointPositionController">
            <joint_name>head_tilt</joint_name>
            <p_gain>1</p_gain>
            <i_gain>0.1</i_gain>
            <d_gain>0.01</d_gain>
            <i_max>1</i_max>
            <i_min>-1</i_min>
            <cmd_max>1000</cmd_max>
            <cmd_min>-1000</cmd_min>
        </plugin>
        <link name='base'>
            <inertial>
                <pose>-0.015010000000000001 0.00012999999999999999 0.065820000000000004 0 0 0</pose>
                <mass>1.34928</mass>
                <inertia>
                    <ixx>0.0034049899999999988</ixx>
                    <ixy>5.7199999999999986e-06</ixy>
                    <ixz>-4.256000000000008e-05</ixz>
                    <iyy>0.0029693900000000001</iyy>
                    <iyz>-5.8999999999999943e-07</iyz>
                    <izz>0.0031733099999999999</izz>
                </inertia>
            </inertial>
            <collision name='base_fixed_joint_lump__body_link_collision'>
                <pose>0 0 0 0 0 0</pose>
                <geometry>
                    <mesh>
                        <scale>0.001 0.001 0.001</scale>
                        <uri>file:///src/altair_simulation/meshes/body.stl</uri>
                    </mesh>
                </geometry>
                <surface>
                    <contact>
                        <ode />
                    </contact>
                    <friction>
                        <ode>
                            <mu>0.20000000000000001</mu>
                            <mu2>0.20000000000000001</mu2>
                        </ode>
                    </friction>
                </surface>
            </collision>
            <visual name='base_fixed_joint_lump__body_link_visual'>
                <pose>0 0 0 0 0 0</pose>
                <geometry>
                    <mesh>
                        <scale>0.001 0.001 0.001</scale>
                        <uri>file:///src/altair_simulation/meshes/body.stl</uri>
                    </mesh>
                </geometry>
                <material>
                    <diffuse>0.75000006 0.75000006 0.75000006 1</diffuse>
                    <ambient>0.75000006 0.75000006 0.75000006 1</ambient>
                </material>
            </visual>
            <self_collide>false</self_collide>
            <gravity>true</gravity>
            <sensor name='imu_sensor' type='imu'>
                <pose>0 0 0 0 0 0</pose>
                <topic>gazebo/imu</topic>
                <update_rate>100</update_rate>
                <enable_metrics>false</enable_metrics>
                <imu>
                    <orientation_reference_frame>
                        <localization>CUSTOM</localization>
                        <custom_rpy>0 0 0</custom_rpy>
                        <grav_dir_x>1 0 0</grav_dir_x>
                    </orientation_reference_frame>
                    <angular_velocity>
                        <x>
                            <noise type='none'>
                                <mean>0</mean>
                                <stddev>0</stddev>
                                <bias_mean>0</bias_mean>
                                <bias_stddev>0</bias_stddev>
                                <dynamic_bias_stddev>0</dynamic_bias_stddev>
                                <dynamic_bias_correlation_time>0</dynamic_bias_correlation_time>
                                <precision>0</precision>
                            </noise>
                        </x>
                        <y>
                            <noise type='none'>
                                <mean>0</mean>
                                <stddev>0</stddev>
                                <bias_mean>0</bias_mean>
                                <bias_stddev>0</bias_stddev>
                                <dynamic_bias_stddev>0</dynamic_bias_stddev>
                                <dynamic_bias_correlation_time>0</dynamic_bias_correlation_time>
                                <precision>0</precision>
                            </noise>
                        </y>
                        <z>
                            <noise type='none'>
                                <mean>0</mean>
                                <stddev>0</stddev>
                                <bias_mean>0</bias_mean>
                                <bias_stddev>0</bias_stddev>
                                <dynamic_bias_stddev>0</dynamic_bias_stddev>
                                <dynamic_bias_correlation_time>0</dynamic_bias_correlation_time>
                                <precision>0</precision>
                            </noise>
                        </z>
                    </angular_velocity>
                    <linear_acceleration>
                        <x>
                            <noise type='none'>
                                <mean>0</mean>
                                <stddev>0</stddev>
                                <bias_mean>0</bias_mean>
                                <bias_stddev>0</bias_stddev>
                                <dynamic_bias_stddev>0</dynamic_bias_stddev>
                                <dynamic_bias_correlation_time>0</dynamic_bias_correlation_time>
                                <precision>0</precision>
                            </noise>
                        </x>
                        <y>
                            <noise type='none'>
                                <mean>0</mean>
                                <stddev>0</stddev>
                                <bias_mean>0</bias_mean>
                                <bias_stddev>0</bias_stddev>
                                <dynamic_bias_stddev>0</dynamic_bias_stddev>
                                <dynamic_bias_correlation_time>0</dynamic_bias_correlation_time>
                                <precision>0</precision>
                            </noise>
                        </y>
                        <z>
                            <noise type='none'>
                                <mean>0</mean>
                                <stddev>0</stddev>
                                <bias_mean>0</bias_mean>
                                <bias_stddev>0</bias_stddev>
                                <dynamic_bias_stddev>0</dynamic_bias_stddev>
                                <dynamic_bias_correlation_time>0</dynamic_bias_correlation_time>
                                <precision>0</precision>
                            </noise>
                        </z>
                    </linear_acceleration>
                    <enable_orientation>true</enable_orientation>
                </imu>
            </sensor>
            <pose>0 0 0 0 0 0</pose>
            <enable_wind>false</enable_wind>
        </link>
        <joint name='head_pan' type='revolute'>
            <pose>0 0 0 0 0 0</pose>
            <parent>base</parent>
            <child>head_pan_link</child>
            <axis>
                <xyz>0 0 1</xyz>
                <limit>
                    <lower>-2.8274333882308138</lower>
                    <upper>2.8274333882308138</upper>
                    <effort>1000</effort>
                    <velocity>100</velocity>
                    <stiffness>100000000</stiffness>
                    <dissipation>1</dissipation>
                </limit>
                <dynamics>
                    <spring_reference>0</spring_reference>
                    <spring_stiffness>0</spring_stiffness>
                    <damping>0.10000000000000001</damping>
                    <friction>0</friction>
                </dynamics>
            </axis>
        </joint>
        <link name='head_pan_link'>
            <pose>-0.00099999999999988987 0 0.13650000000000001 0 0 0</pose>
            <inertial>
                <pose>0.00233 0 0.0082299999999999995 0 0 0</pose>
                <mass>0.01176</mass>
                <inertia>
                    <ixx>3.9700000000000001e-06</ixx>
                    <ixy>0</ixy>
                    <ixz>-3.1e-07</ixz>
                    <iyy>1.6500000000000001e-06</iyy>
                    <iyz>0</iyz>
                    <izz>3.8700000000000002e-06</izz>
                </inertia>
            </inertial>
            <collision name='head_pan_link_collision'>
                <pose>0 0 0 0 0 0</pose>
                <geometry>
                    <mesh>
                        <scale>0.001 0.001 0.001</scale>
                        <uri>file:///src/altair_simulation/meshes/h1.stl</uri>
                    </mesh>
                </geometry>
                <surface>
                    <contact>
                        <ode />
                    </contact>
                    <friction>
                        <ode>
                            <mu>0.20000000000000001</mu>
                            <mu2>0.20000000000000001</mu2>
                        </ode>
                    </friction>
                </surface>
            </collision>
            <visual name='head_pan_link_visual'>
                <pose>0 0 0 0 0 0</pose>
                <geometry>
                    <mesh>
                        <scale>0.001 0.001 0.001</scale>
                        <uri>file:///src/altair_simulation/meshes/h1.stl</uri>
                    </mesh>
                </geometry>
                <material>
                    <diffuse>0.75000006 0.75000006 0.75000006 1</diffuse>
                    <ambient>0.75000006 0.75000006 0.75000006 1</ambient>
                </material>
            </visual>
            <self_collide>false</self_collide>
            <enable_wind>false</enable_wind>
        </link>
        <joint name='head_tilt' type='revolute'>
            <pose>0 0 0 0 0 0</pose>
            <parent>head_pan_link</parent>
            <child>head_tilt_link</child>
            <axis>
                <xyz>0 -1 0</xyz>
                <limit>
                    <lower>-2.8274333882308138</lower>
                    <upper>2.8274333882308138</upper>
                    <effort>1000</effort>
                    <velocity>100</velocity>
                    <stiffness>100000000</stiffness>
                    <dissipation>1</dissipation>
                </limit>
                <dynamics>
                    <spring_reference>0</spring_reference>
                    <spring_stiffness>0</spring_stiffness>
                    <damping>0.10000000000000001</damping>
                    <friction>0</friction>
                </dynamics>
            </axis>
        </joint>
        <link name='head_tilt_link'>
            <pose>0.009000000000000119 0.019 0.16499999999999998 0 0 0</pose>
            <inertial>
                <pose>0.0023 -0.018630000000000001 0.027699999999999999 0 0 0</pose>
                <mass>0.13630999999999999</mass>
                <inertia>
                    <ixx>0.00010611999999999999</ixx>
                    <ixy>1.1000000000000001e-07</ixy>
                    <ixz>-9.0999999999999993e-06</ixz>
                    <iyy>8.721e-05</iyy>
                    <iyz>8.4e-07</iyz>
                    <izz>4.5290000000000002e-05</izz>
                </inertia>
            </inertial>
            <collision name='head_tilt_link_collision'>
                <pose>0 0 0 0 0 0</pose>
                <geometry>
                    <mesh>
                        <scale>0.001 0.001 0.001</scale>
                        <uri>file:///src/altair_simulation/meshes/h2.stl</uri>
                    </mesh>
                </geometry>
                <surface>
                    <contact>
                        <ode />
                    </contact>
                    <friction>
                        <ode>
                            <mu>0.20000000000000001</mu>
                            <mu2>0.20000000000000001</mu2>
                        </ode>
                    </friction>
                </surface>
            </collision>
            <visual name='head_tilt_link_visual'>
                <pose>0 0 0 0 0 0</pose>
                <geometry>
                    <mesh>
                        <scale>0.001 0.001 0.001</scale>
                        <uri>file:///src/altair_simulation/meshes/h2.stl</uri>
                    </mesh>
                </geometry>
                <material>
                    <diffuse>0.75000006 0.75000006 0.75000006 1</diffuse>
                    <ambient>0.75000006 0.75000006 0.75000006 1</ambient>
                </material>
            </visual>
            <self_collide>false</self_collide>
            <sensor name='camera' type='camera'>
                <pose>0.014250000000000001 -0.019 0.049750000000000003 0 0 0</pose>
                <topic>gazebo/camera/image_raw</topic>
                <update_rate>30</update_rate>
                <enable_metrics>false</enable_metrics>
                <camera name='__default__'>
                    <pose>0 0 0 0 0 0</pose>
                    <horizontal_fov>1.0123</horizontal_fov>
                    <image>
                        <width>320</width>
                        <height>200</height>
                        <format>RGB_INT8</format>
                        <anti_aliasing>4</anti_aliasing>
                    </image>
                    <camera_info_topic>gazebo/camera/camera_info</camera_info_topic>
                    <trigger_topic></trigger_topic>
                    <triggered>false</triggered>
                    <clip>
                        <near>0.001</near>
                        <far>100</far>
                    </clip>
                    <save enabled='false'>
                        <path>__default__</path>
                    </save>
                    <visibility_mask>4294967295</visibility_mask>
                    <noise>
                        <type>none</type>
                        <mean>0</mean>
                        <stddev>0</stddev>
                    </noise>
                    <distortion>
                        <k1>0</k1>
                        <k2>0</k2>
                        <k3>0</k3>
                        <p1>0</p1>
                        <p2>0</p2>
                        <center>0.5 0.5</center>
                    </distortion>
                    <lens>
                        <type>stereographic</type>
                        <scale_to_hfov>true</scale_to_hfov>
                        <cutoff_angle>1.5707963267948966</cutoff_angle>
                        <env_texture_size>256</env_texture_size>
                    </lens>
                    <optical_frame_id></optical_frame_id>
                </camera>
            </sensor>
            <enable_wind>false</enable_wind>
        </link>
        <joint name='l_hip_yaw' type='revolute'>
            <pose>0 0 0 0 0 0</pose>
            <parent>base</parent>
            <child>l_hip_yaw_link</child>
            <axis>
                <xyz>0 0 -1</xyz>
                <limit>
                    <lower>-2.8274333882308138</lower>
                    <upper>2.8274333882308138</upper>
                    <effort>1000</effort>
                    <velocity>100</velocity>
                    <stiffness>100000000</stiffness>
                    <dissipation>1</dissipation>
                </limit>
                <dynamics>
                    <spring_reference>0</spring_reference>
                    <spring_stiffness>0</spring_stiffness>
                    <damping>0.10000000000000001</damping>
                    <friction>0</friction>
                </dynamics>
            </axis>
        </joint>
        <link name='l_hip_yaw_link'>
            <pose>0 0.035000000000000003 0 0 0 0</pose>
            <inertial>
                <pose>-0.00157 0 -0.0077400000000000004 0 0 0</pose>
                <mass>0.011809999999999999</mass>
                <inertia>
                    <ixx>1.5099999999999999e-06</ixx>
                    <ixy>0</ixy>
                    <ixz>1e-08</ixz>
                    <iyy>4.3000000000000003e-06</iyy>
                    <iyz>0</iyz>
                    <izz>4.1200000000000004e-06</izz>
                </inertia>
            </inertial>
            <collision name='l_hip_yaw_link_collision'>
                <pose>0 0 0 0 0 0</pose>
                <geometry>
                    <mesh>
                        <scale>0.001 0.001 0.001</scale>
                        <uri>file:///src/altair_simulation/meshes/ll1.stl</uri>
                    </mesh>
                </geometry>
                <surface>
                    <contact>
                        <ode />
                    </contact>
                    <friction>
                        <ode>
                            <mu>0.20000000000000001</mu>
                            <mu2>0.20000000000000001</mu2>
                        </ode>
                    </friction>
                </surface>
            </collision>
            <visual name='l_hip_yaw_link_visual'>
                <pose>0 0 0 0 0 0</pose>
                <geometry>
                    <mesh>
                        <scale>0.001 0.001 0.001</scale>
                        <uri>file:///src/altair_simulation/meshes/ll1.stl</uri>
                    </mesh>
                </geometry>
                <material>
                    <diffuse>0.75000006 0.75000006 0.75000006 1</diffuse>
                    <ambient>0.75000006 0.75000006 0.75000006 1</ambient>
                </material>
            </visual>
            <self_collide>false</self_collide>
            <enable_wind>false</enable_wind>
        </link>
        <joint name='l_hip_roll' type='revolute'>
            <pose>0 0 0 0 0 0</pose>
            <parent>l_hip_yaw_link</parent>
            <child>l_hip_roll_link</child>
            <axis>
                <xyz>-1 0 0</xyz>
                <limit>
                    <lower>-2.8274333882308138</lower>
                    <upper>2.8274333882308138</upper>
                    <effort>1000</effort>
                    <velocity>100</velocity>
                    <stiffness>100000000</stiffness>
                    <dissipation>1</dissipation>
                </limit>
                <dynamics>
                    <spring_reference>0</spring_reference>
                    <spring_stiffness>0</spring_stiffness>
                    <damping>0.10000000000000001</damping>
                    <friction>0</friction>
                </dynamics>
            </axis>
        </joint>
        <link name='l_hip_roll_link'>
            <pose>-0.024000000000000021 0.035000000000000003 -0.028500000000000025 0 0 0</pose>
            <inertial>
                <pose>0.0038800000000000002 0.00027999999999999998 -0.01214 0 0 0</pose>
                <mass>0.17885999999999999</mass>
                <inertia>
                    <ixx>4.6610000000000003e-05</ixx>
                    <ixy>-1.0100000000000001e-06</ixy>
                    <ixz>-1.31e-06</ixz>
                    <iyy>0.00012522999999999999</iyy>
                    <iyz>-5.9999999999999995e-08</iyz>
                    <izz>0.00010857</izz>
                </inertia>
            </inertial>
            <collision name='l_hip_roll_link_collision'>
                <pose>0 0 0 0 0 0</pose>
                <geometry>
                    <mesh>
                        <scale>0.001 0.001 0.001</scale>
                        <uri>file:///src/altair_simulation/meshes/ll2.stl</uri>
                    </mesh>
                </geometry>
                <surface>
                    <contact>
                        <ode />
                    </contact>
                    <friction>
                        <ode>
                            <mu>0.20000000000000001</mu>
                            <mu2>0.20000000000000001</mu2>
                        </ode>
                    </friction>
                </surface>
            </collision>
            <visual name='l_hip_roll_link_visual'>
                <pose>0 0 0 0 0 0</pose>
                <geometry>
                    <mesh>
                        <scale>0.001 0.001 0.001</scale>
                        <uri>file:///src/altair_simulation/meshes/ll2.stl</uri>
                    </mesh>
                </geometry>
                <material>
                    <diffuse>0.75000006 0.75000006 0.75000006 1</diffuse>
                    <ambient>0.75000006 0.75000006 0.75000006 1</ambient>
                </material>
            </visual>
            <self_collide>false</self_collide>
            <enable_wind>false</enable_wind>
        </link>
        <joint name='l_hip_pitch' type='revolute'>
            <pose>0 0 0 0 0 0</pose>
            <parent>l_hip_roll_link</parent>
            <child>l_hip_pitch_link</child>
            <axis>
                <xyz>0 1 0</xyz>
                <limit>
                    <lower>-2.8274333882308138</lower>
                    <upper>2.8274333882308138</upper>
                    <effort>1000</effort>
                    <velocity>100</velocity>
                    <stiffness>100000000</stiffness>
                    <dissipation>1</dissipation>
                </limit>
                <dynamics>
                    <spring_reference>0</spring_reference>
                    <spring_stiffness>0</spring_stiffness>
                    <damping>0.10000000000000001</damping>
                    <friction>0</friction>
                </dynamics>
            </axis>
        </joint>
        <link name='l_hip_pitch_link'>
            <pose>9.9999999999988987e-05 0.054000000000000006 -0.028500000000000025 0 0 0</pose>
            <inertial>
                <pose>0.00059000000000000003 -0.019009999999999999 -0.084080000000000002 0 0 0</pose>
                <mass>0.11543</mass>
                <inertia>
                    <ixx>0.00010499</ixx>
                    <ixy>-1e-08</ixy>
                    <ixz>-7.0999999999999998e-07</ixz>
                    <iyy>9.6130000000000003e-05</iyy>
                    <iyz>3.5300000000000001e-06</iyz>
                    <izz>2.493e-05</izz>
                </inertia>
            </inertial>
            <collision name='l_hip_pitch_link_collision'>
                <pose>0 0 0 0 0 0</pose>
                <geometry>
                    <mesh>
                        <scale>0.001 0.001 0.001</scale>
                        <uri>file:///src/altair_simulation/meshes/ll3.stl</uri>
                    </mesh>
                </geometry>
                <surface>
                    <contact>
                        <ode />
                    </contact>
                    <friction>
                        <ode>
                            <mu>0.20000000000000001</mu>
                            <mu2>0.20000000000000001</mu2>
                        </ode>
                    </friction>
                </surface>
            </collision>
            <visual name='l_hip_pitch_link_visual'>
                <pose>0 0 0 0 0 0</pose>
                <geometry>
                    <mesh>
                        <scale>0.001 0.001 0.001</scale>
                        <uri>file:///src/altair_simulation/meshes/ll3.stl</uri>
                    </mesh>
                </geometry>
                <material>
                    <diffuse>0.75000006 0.75000006 0.75000006 1</diffuse>
                    <ambient>0.75000006 0.75000006 0.75000006 1</ambient>
                </material>
            </visual>
            <self_collide>false</self_collide>
            <enable_wind>false</enable_wind>
        </link>
        <joint name='l_knee' type='revolute'>
            <pose>0 0 0 0 0 0</pose>
            <parent>l_hip_pitch_link</parent>
            <child>l_knee_link</child>
            <axis>
                <xyz>0 1 0</xyz>
                <limit>
                    <lower>-2.8274333882308138</lower>
                    <upper>2.8274333882308138</upper>
                    <effort>1000</effort>
                    <velocity>100</velocity>
                    <stiffness>100000000</stiffness>
                    <dissipation>1</dissipation>
                </limit>
                <dynamics>
                    <spring_reference>0</spring_reference>
                    <spring_stiffness>0</spring_stiffness>
                    <damping>0.10000000000000001</damping>
                    <friction>0</friction>
                </dynamics>
            </axis>
        </joint>
        <link name='l_knee_link'>
            <pose>9.9999999999988987e-05 0.054000000000000006 -0.13865000000000002 0 0 0</pose>
            <inertial>
                <pose>0 -0.021510000000000001 -0.055 0 0 0</pose>
                <mass>0.040149999999999998</mass>
                <inertia>
                    <ixx>3.7150000000000002e-05</ixx>
                    <ixy>0</ixy>
                    <ixz>0</ixz>
                    <iyy>2.7509999999999999e-05</iyy>
                    <iyz>0</iyz>
                    <izz>1.5109999999999999e-05</izz>
                </inertia>
            </inertial>
            <collision name='l_knee_link_collision'>
                <pose>0 0 0 0 0 0</pose>
                <geometry>
                    <mesh>
                        <scale>0.001 0.001 0.001</scale>
                        <uri>file:///src/altair_simulation/meshes/ll4.stl</uri>
                    </mesh>
                </geometry>
                <surface>
                    <contact>
                        <ode />
                    </contact>
                    <friction>
                        <ode>
                            <mu>0.20000000000000001</mu>
                            <mu2>0.20000000000000001</mu2>
                        </ode>
                    </friction>
                </surface>
            </collision>
            <visual name='l_knee_link_visual'>
                <pose>0 0 0 0 0 0</pose>
                <geometry>
                    <mesh>
                        <scale>0.001 0.001 0.001</scale>
                        <uri>file:///src/altair_simulation/meshes/ll4.stl</uri>
                    </mesh>
                </geometry>
                <material>
                    <diffuse>0.75000006 0.75000006 0.75000006 1</diffuse>
                    <ambient>0.75000006 0.75000006 0.75000006 1</ambient>
                </material>
            </visual>
            <self_collide>false</self_collide>
            <enable_wind>false</enable_wind>
        </link>
        <joint name='l_ank_pitch' type='revolute'>
            <pose>0 0 0 0 0 0</pose>
            <parent>l_knee_link</parent>
            <child>l_ank_pitch_link</child>
            <axis>
                <xyz>0 -1 0</xyz>
                <limit>
                    <lower>-2.8274333882308138</lower>
                    <upper>2.8274333882308138</upper>
                    <effort>1000</effort>
                    <velocity>100</velocity>
                    <stiffness>100000000</stiffness>
                    <dissipation>1</dissipation>
                </limit>
                <dynamics>
                    <spring_reference>0</spring_reference>
                    <spring_stiffness>0</spring_stiffness>
                    <damping>0.10000000000000001</damping>
                    <friction>0</friction>
                </dynamics>
            </axis>
        </joint>
        <link name='l_ank_pitch_link'>
            <pose>9.9999999999988987e-05 0.054000000000000006 -0.24865000000000004 0 0 0</pose>
            <inertial>
                <pose>-0.020219999999999998 -0.018720000000000001 0.01214 0 0 0</pose>
                <mass>0.17885999999999999</mass>
                <inertia>
                    <ixx>4.6610000000000003e-05</ixx>
                    <ixy>-1.0100000000000001e-06</ixy>
                    <ixz>1.31e-06</ixz>
                    <iyy>0.00012522999999999999</iyy>
                    <iyz>5.9999999999999995e-08</iyz>
                    <izz>0.00010857</izz>
                </inertia>
            </inertial>
            <collision name='l_ank_pitch_link_collision'>
                <pose>0 0 0 0 0 0</pose>
                <geometry>
                    <mesh>
                        <scale>0.001 0.001 0.001</scale>
                        <uri>file:///src/altair_simulation/meshes/ll5.stl</uri>
                    </mesh>
                </geometry>
                <surface>
                    <contact>
                        <ode />
                    </contact>
                    <friction>
                        <ode>
                            <mu>0.20000000000000001</mu>
                            <mu2>0.20000000000000001</mu2>
                        </ode>
                    </friction>
                </surface>
            </collision>
            <visual name='l_ank_pitch_link_visual'>
                <pose>0 0 0 0 0 0</pose>
                <geometry>
                    <mesh>
                        <scale>0.001 0.001 0.001</scale>
                        <uri>file:///src/altair_simulation/meshes/ll5.stl</uri>
                    </mesh>
                </geometry>
                <material>
                    <diffuse>0.75000006 0.75000006 0.75000006 1</diffuse>
                    <ambient>0.75000006 0.75000006 0.75000006 1</ambient>
                </material>
            </visual>
            <self_collide>false</self_collide>
            <enable_wind>false</enable_wind>
        </link>
        <joint name='l_ank_roll' type='revolute'>
            <pose>0 0 0 0 0 0</pose>
            <parent>l_ank_pitch_link</parent>
            <child>l_ank_roll_link</child>
            <axis>
                <xyz>1 0 0</xyz>
                <limit>
                    <lower>-2.8274333882308138</lower>
                    <upper>2.8274333882308138</upper>
                    <effort>1000</effort>
                    <velocity>100</velocity>
                    <stiffness>100000000</stiffness>
                    <dissipation>1</dissipation>
                </limit>
                <dynamics>
                    <spring_reference>0</spring_reference>
                    <spring_stiffness>0</spring_stiffness>
                    <damping>0.10000000000000001</damping>
                    <friction>0</friction>
                </dynamics>
            </axis>
        </joint>
        <link name='l_ank_roll_link'>
            <pose>-0.024000000000000021 0.035000000000000003 -0.24865000000000004 0 0 0</pose>
            <inertial>
                <pose>0.023730000000000001 0.010370000000000001 -0.0276 0 0 0</pose>
                <mass>0.069339999999999999</mass>
                <inertia>
                    <ixx>4.0339999999999997e-05</ixx>
                    <ixy>-1.9000000000000001e-07</ixy>
                    <ixz>1.1999999999999999e-07</ixz>
                    <iyy>7.8739999999999995e-05</iyy>
                    <iyz>1.0100000000000001e-06</iyz>
                    <izz>0.00011579</izz>
                </inertia>
            </inertial>
            <collision name='l_ank_roll_link_collision'>
                <pose>0 0 0 0 0 0</pose>
                <geometry>
                    <mesh>
                        <scale>0.001 0.001 0.001</scale>
                        <uri>file:///src/altair_simulation/meshes/ll6.stl</uri>
                    </mesh>
                </geometry>
                <surface>
                    <contact>
                        <ode>
                            <kp>100000</kp>
                            <kd>100</kd>
                            <max_vel>1</max_vel>
                            <min_depth>0.001</min_depth>
                        </ode>
                    </contact>
                    <friction>
                        <ode>
                            <mu>1.5</mu>
                            <mu2>1.5</mu2>
                            <fdir1>1 0 0</fdir1>
                        </ode>
                    </friction>
                </surface>
            </collision>
            <visual name='l_ank_roll_link_visual'>
                <pose>0 0 0 0 0 0</pose>
                <geometry>
                    <mesh>
                        <scale>0.001 0.001 0.001</scale>
                        <uri>file:///src/altair_simulation/meshes/ll6.stl</uri>
                    </mesh>
                </geometry>
                <material>
                    <diffuse>0.75000006 0.75000006 0.75000006 1</diffuse>
                    <ambient>0.75000006 0.75000006 0.75000006 1</ambient>
                </material>
            </visual>
            <enable_wind>false</enable_wind>
        </link>
        <joint name='l_sho_pitch' type='revolute'>
            <pose>0 0 0 0 0 0</pose>
            <parent>base</parent>
            <child>l_sho_pitch_link</child>
            <axis>
                <xyz>0 1 0</xyz>
                <limit>
                    <lower>-2.8274333882308138</lower>
                    <upper>2.8274333882308138</upper>
                    <effort>1000</effort>
                    <velocity>100</velocity>
                    <stiffness>100000000</stiffness>
                    <dissipation>1</dissipation>
                </limit>
                <dynamics>
                    <spring_reference>0</spring_reference>
                    <spring_stiffness>0</spring_stiffness>
                    <damping>0.10000000000000001</damping>
                    <friction>0</friction>
                </dynamics>
            </axis>
        </joint>
        <link name='l_sho_pitch_link'>
            <pose>-0.00099999999999988987 0.059999999999999998 0.11099999999999999 0 0 0</pose>
            <inertial>
                <pose>0 0.0082299999999999995 -0.00233 0 0 0</pose>
                <mass>0.01176</mass>
                <inertia>
                    <ixx>1.6500000000000001e-06</ixx>
                    <ixy>0</ixy>
                    <ixz>0</ixz>
                    <iyy>3.8700000000000002e-06</iyy>
                    <iyz>3.1e-07</iyz>
                    <izz>3.9700000000000001e-06</izz>
                </inertia>
            </inertial>
            <collision name='l_sho_pitch_link_collision'>
                <pose>0 0 0 0 0 0</pose>
                <geometry>
                    <mesh>
                        <scale>0.001 0.001 0.001</scale>
                        <uri>file:///src/altair_simulation/meshes/la1.stl</uri>
                    </mesh>
                </geometry>
                <surface>
                    <contact>
                        <ode />
                    </contact>
                    <friction>
                        <ode>
                            <mu>0.20000000000000001</mu>
                            <mu2>0.20000000000000001</mu2>
                        </ode>
                    </friction>
                </surface>
            </collision>
            <visual name='l_sho_pitch_link_visual'>
                <pose>0 0 0 0 0 0</pose>
                <geometry>
                    <mesh>
                        <scale>0.001 0.001 0.001</scale>
                        <uri>file:///src/altair_simulation/meshes/la1.stl</uri>
                    </mesh>
                </geometry>
                <material>
                    <diffuse>0.75000006 0.75000006 0.75000006 1</diffuse>
                    <ambient>0.75000006 0.75000006 0.75000006 1</ambient>
                </material>
            </visual>
            <self_collide>false</self_collide>
            <enable_wind>false</enable_wind>
        </link>
        <joint name='l_sho_roll' type='revolute'>
            <pose>0 0 0 0 0 0</pose>
            <parent>l_sho_pitch_link</parent>
            <child>l_sho_roll_link</child>
            <axis>
                <xyz>-1 0 0</xyz>
                <limit>
                    <lower>-2.8274333882308138</lower>
                    <upper>2.8274333882308138</upper>
                    <effort>1000</effort>
                    <velocity>100</velocity>
                    <stiffness>100000000</stiffness>
                    <dissipation>1</dissipation>
                </limit>
                <dynamics>
                    <spring_reference>0</spring_reference>
                    <spring_stiffness>0</spring_stiffness>
                    <damping>0.10000000000000001</damping>
                    <friction>0</friction>
                </dynamics>
            </axis>
        </joint>
        <link name='l_sho_roll_link'>
            <pose>0.018000000000000016 0.088499999999999995 0.10099999999999998 0 0 0</pose>
            <inertial>
                <pose>-0.018440000000000002 0.04514 0.00027999999999999998 0 0 0</pose>
                <mass>0.17757999999999999</mass>
                <inertia>
                    <ixx>0.00022803999999999999</ixx>
                    <ixy>-1e-08</ixy>
                    <ixz>2.9999999999999997e-08</ixz>
                    <iyy>3.042e-05</iyy>
                    <iyz>5.8999999999999996e-07</iyz>
                    <izz>0.00023473999999999999</izz>
                </inertia>
            </inertial>
            <collision name='l_sho_roll_link_collision'>
                <pose>0 0 0 0 0 0</pose>
                <geometry>
                    <mesh>
                        <scale>0.001 0.001 0.001</scale>
                        <uri>file:///src/altair_simulation/meshes/la2.stl</uri>
                    </mesh>
                </geometry>
                <surface>
                    <contact>
                        <ode />
                    </contact>
                    <friction>
                        <ode>
                            <mu>0.20000000000000001</mu>
                            <mu2>0.20000000000000001</mu2>
                        </ode>
                    </friction>
                </surface>
            </collision>
            <visual name='l_sho_roll_link_visual'>
                <pose>0 0 0 0 0 0</pose>
                <geometry>
                    <mesh>
                        <scale>0.001 0.001 0.001</scale>
                        <uri>file:///src/altair_simulation/meshes/la2.stl</uri>
                    </mesh>
                </geometry>
                <material>
                    <diffuse>0.75000006 0.75000006 0.75000006 1</diffuse>
                    <ambient>0.75000006 0.75000006 0.75000006 1</ambient>
                </material>
            </visual>
            <self_collide>false</self_collide>
            <enable_wind>false</enable_wind>
        </link>
        <joint name='l_el' type='revolute'>
            <pose>0 0 0 0 0 0</pose>
            <parent>l_sho_roll_link</parent>
            <child>l_el_link</child>
            <axis>
                <xyz>1 0 0</xyz>
                <limit>
                    <lower>-2.8274333882308138</lower>
                    <upper>2.8274333882308138</upper>
                    <effort>1000</effort>
                    <velocity>100</velocity>
                    <stiffness>100000000</stiffness>
                    <dissipation>1</dissipation>
                </limit>
                <dynamics>
                    <spring_reference>0</spring_reference>
                    <spring_stiffness>0</spring_stiffness>
                    <damping>0.10000000000000001</damping>
                    <friction>0</friction>
                </dynamics>
            </axis>
        </joint>
        <link name='l_el_link'>
            <pose>0.018000000000000016 0.1789 0.10089999999999999 0 0 0</pose>
            <inertial>
                <pose>-0.019 0.070330000000000004 0.0038 0 0 0</pose>
                <mass>0.041270000000000001</mass>
                <inertia>
                    <ixx>6.1959999999999996e-05</ixx>
                    <ixy>0</ixy>
                    <ixz>0</ixz>
                    <iyy>1.2310000000000001e-05</iyy>
                    <iyz>-3.72e-06</iyz>
                    <izz>6.8540000000000004e-05</izz>
                </inertia>
            </inertial>
            <collision name='l_el_link_collision'>
                <pose>0 0 0 0 0 0</pose>
                <geometry>
                    <mesh>
                        <scale>0.001 0.001 0.001</scale>
                        <uri>file:///src/altair_simulation/meshes/la3.stl</uri>
                    </mesh>
                </geometry>
                <surface>
                    <contact>
                        <ode />
                    </contact>
                    <friction>
                        <ode>
                            <mu>0.20000000000000001</mu>
                            <mu2>0.20000000000000001</mu2>
                        </ode>
                    </friction>
                </surface>
            </collision>
            <visual name='l_el_link_visual'>
                <pose>0 0 0 0 0 0</pose>
                <geometry>
                    <mesh>
                        <scale>0.001 0.001 0.001</scale>
                        <uri>file:///src/altair_simulation/meshes/la3.stl</uri>
                    </mesh>
                </geometry>
                <material>
                    <diffuse>0.75000006 0.75000006 0.75000006 1</diffuse>
                    <ambient>0.75000006 0.75000006 0.75000006 1</ambient>
                </material>
            </visual>
            <self_collide>false</self_collide>
            <enable_wind>false</enable_wind>
        </link>
        <joint name='r_hip_yaw' type='revolute'>
            <pose>0 0 0 0 0 0</pose>
            <parent>base</parent>
            <child>r_hip_yaw_link</child>
            <axis>
                <xyz>0 0 -1</xyz>
                <limit>
                    <lower>-2.8274333882308138</lower>
                    <upper>2.8274333882308138</upper>
                    <effort>1000</effort>
                    <velocity>100</velocity>
                    <stiffness>100000000</stiffness>
                    <dissipation>1</dissipation>
                </limit>
                <dynamics>
                    <spring_reference>0</spring_reference>
                    <spring_stiffness>0</spring_stiffness>
                    <damping>0.10000000000000001</damping>
                    <friction>0</friction>
                </dynamics>
            </axis>
        </joint>
        <link name='r_hip_yaw_link'>
            <pose>0 -0.035000000000000003 0 0 0 0</pose>
            <inertial>
                <pose>-0.00157 0 -0.0077400000000000004 0 0 0</pose>
                <mass>0.011809999999999999</mass>
                <inertia>
                    <ixx>1.5099999999999999e-06</ixx>
                    <ixy>0</ixy>
                    <ixz>1e-08</ixz>
                    <iyy>4.3000000000000003e-06</iyy>
                    <iyz>0</iyz>
                    <izz>4.1200000000000004e-06</izz>
                </inertia>
            </inertial>
            <collision name='r_hip_yaw_link_collision'>
                <pose>0 0 0 0 0 0</pose>
                <geometry>
                    <mesh>
                        <scale>0.001 0.001 0.001</scale>
                        <uri>file:///src/altair_simulation/meshes/rl1.stl</uri>
                    </mesh>
                </geometry>
                <surface>
                    <contact>
                        <ode />
                    </contact>
                    <friction>
                        <ode>
                            <mu>0.20000000000000001</mu>
                            <mu2>0.20000000000000001</mu2>
                        </ode>
                    </friction>
                </surface>
            </collision>
            <visual name='r_hip_yaw_link_visual'>
                <pose>0 0 0 0 0 0</pose>
                <geometry>
                    <mesh>
                        <scale>0.001 0.001 0.001</scale>
                        <uri>file:///src/altair_simulation/meshes/rl1.stl</uri>
                    </mesh>
                </geometry>
                <material>
                    <diffuse>0.75000006 0.75000006 0.75000006 1</diffuse>
                    <ambient>0.75000006 0.75000006 0.75000006 1</ambient>
                </material>
            </visual>
            <self_collide>false</self_collide>
            <enable_wind>false</enable_wind>
        </link>
        <joint name='r_hip_roll' type='revolute'>
            <pose>0 0 0 0 0 0</pose>
            <parent>r_hip_yaw_link</parent>
            <child>r_hip_roll_link</child>
            <axis>
                <xyz>-1 0 0</xyz>
                <limit>
                    <lower>-2.8274333882308138</lower>
                    <upper>2.8274333882308138</upper>
                    <effort>1000</effort>
                    <velocity>100</velocity>
                    <stiffness>100000000</stiffness>
                    <dissipation>1</dissipation>
                </limit>
                <dynamics>
                    <spring_reference>0</spring_reference>
                    <spring_stiffness>0</spring_stiffness>
                    <damping>0.10000000000000001</damping>
                    <friction>0</friction>
                </dynamics>
            </axis>
        </joint>
        <link name='r_hip_roll_link'>
            <pose>-0.024000000000000021 -0.035000000000000003 -0.028500000000000025 0 0 0</pose>
            <inertial>
                <pose>0.0038800000000000002 -0.00027999999999999998 -0.01214 0 0 0</pose>
                <mass>0.17885999999999999</mass>
                <inertia>
                    <ixx>4.6610000000000003e-05</ixx>
                    <ixy>1.0100000000000001e-06</ixy>
                    <ixz>-1.31e-06</ixz>
                    <iyy>0.00012522999999999999</iyy>
                    <iyz>5.9999999999999995e-08</iyz>
                    <izz>0.00010857</izz>
                </inertia>
            </inertial>
            <collision name='r_hip_roll_link_collision'>
                <pose>0 0 0 0 0 0</pose>
                <geometry>
                    <mesh>
                        <scale>0.001 0.001 0.001</scale>
                        <uri>file:///src/altair_simulation/meshes/rl2.stl</uri>
                    </mesh>
                </geometry>
                <surface>
                    <contact>
                        <ode />
                    </contact>
                    <friction>
                        <ode>
                            <mu>0.20000000000000001</mu>
                            <mu2>0.20000000000000001</mu2>
                        </ode>
                    </friction>
                </surface>
            </collision>
            <visual name='r_hip_roll_link_visual'>
                <pose>0 0 0 0 0 0</pose>
                <geometry>
                    <mesh>
                        <scale>0.001 0.001 0.001</scale>
                        <uri>file:///src/altair_simulation/meshes/rl2.stl</uri>
                    </mesh>
                </geometry>
                <material>
                    <diffuse>0.75000006 0.75000006 0.75000006 1</diffuse>
                    <ambient>0.75000006 0.75000006 0.75000006 1</ambient>
                </material>
            </visual>
            <self_collide>false</self_collide>
            <enable_wind>false</enable_wind>
        </link>
        <joint name='r_hip_pitch' type='revolute'>
            <pose>0 0 0 0 0 0</pose>
            <parent>r_hip_roll_link</parent>
            <child>r_hip_pitch_link</child>
            <axis>
                <xyz>0 -1 0</xyz>
                <limit>
                    <lower>-2.8274333882308138</lower>
                    <upper>2.8274333882308138</upper>
                    <effort>1000</effort>
                    <velocity>100</velocity>
                    <stiffness>100000000</stiffness>
                    <dissipation>1</dissipation>
                </limit>
                <dynamics>
                    <spring_reference>0</spring_reference>
                    <spring_stiffness>0</spring_stiffness>
                    <damping>0.10000000000000001</damping>
                    <friction>0</friction>
                </dynamics>
            </axis>
        </joint>
        <link name='r_hip_pitch_link'>
            <pose>9.9999999999988987e-05 -0.054000000000000006 -0.028500000000000025 0 0 0</pose>
            <inertial>
                <pose>0.00059000000000000003 0.019009999999999999 -0.084080000000000002 0 0 0</pose>
                <mass>0.11543</mass>
                <inertia>
                    <ixx>0.00010499</ixx>
                    <ixy>1e-08</ixy>
                    <ixz>-7.0999999999999998e-07</ixz>
                    <iyy>9.6130000000000003e-05</iyy>
                    <iyz>-3.5300000000000001e-06</iyz>
                    <izz>2.493e-05</izz>
                </inertia>
            </inertial>
            <collision name='r_hip_pitch_link_collision'>
                <pose>0 0 0 0 0 0</pose>
                <geometry>
                    <mesh>
                        <scale>0.001 0.001 0.001</scale>
                        <uri>file:///src/altair_simulation/meshes/rl3.stl</uri>
                    </mesh>
                </geometry>
                <surface>
                    <contact>
                        <ode />
                    </contact>
                    <friction>
                        <ode>
                            <mu>0.20000000000000001</mu>
                            <mu2>0.20000000000000001</mu2>
                        </ode>
                    </friction>
                </surface>
            </collision>
            <visual name='r_hip_pitch_link_visual'>
                <pose>0 0 0 0 0 0</pose>
                <geometry>
                    <mesh>
                        <scale>0.001 0.001 0.001</scale>
                        <uri>file:///src/altair_simulation/meshes/rl3.stl</uri>
                    </mesh>
                </geometry>
                <material>
                    <diffuse>0.75000006 0.75000006 0.75000006 1</diffuse>
                    <ambient>0.75000006 0.75000006 0.75000006 1</ambient>
                </material>
            </visual>
            <self_collide>false</self_collide>
            <enable_wind>false</enable_wind>
        </link>
        <joint name='r_knee' type='revolute'>
            <pose>0 0 0 0 0 0</pose>
            <parent>r_hip_pitch_link</parent>
            <child>r_knee_link</child>
            <axis>
                <xyz>0 -1 0</xyz>
                <limit>
                    <lower>-2.8274333882308138</lower>
                    <upper>2.8274333882308138</upper>
                    <effort>1000</effort>
                    <velocity>100</velocity>
                    <stiffness>100000000</stiffness>
                    <dissipation>1</dissipation>
                </limit>
                <dynamics>
                    <spring_reference>0</spring_reference>
                    <spring_stiffness>0</spring_stiffness>
                    <damping>0.10000000000000001</damping>
                    <friction>0</friction>
                </dynamics>
            </axis>
        </joint>
        <link name='r_knee_link'>
            <pose>9.9999999999988987e-05 -0.054000000000000006 -0.13865000000000002 0 0 0</pose>
            <inertial>
                <pose>0 0.021510000000000001 -0.055 0 0 0</pose>
                <mass>0.040149999999999998</mass>
                <inertia>
                    <ixx>3.7150000000000002e-05</ixx>
                    <ixy>0</ixy>
                    <ixz>0</ixz>
                    <iyy>2.7509999999999999e-05</iyy>
                    <iyz>0</iyz>
                    <izz>1.5109999999999999e-05</izz>
                </inertia>
            </inertial>
            <collision name='r_knee_link_collision'>
                <pose>0 0 0 0 0 0</pose>
                <geometry>
                    <mesh>
                        <scale>0.001 0.001 0.001</scale>
                        <uri>file:///src/altair_simulation/meshes/rl4.stl</uri>
                    </mesh>
                </geometry>
                <surface>
                    <contact>
                        <ode />
                    </contact>
                    <friction>
                        <ode>
                            <mu>0.20000000000000001</mu>
                            <mu2>0.20000000000000001</mu2>
                        </ode>
                    </friction>
                </surface>
            </collision>
            <visual name='r_knee_link_visual'>
                <pose>0 0 0 0 0 0</pose>
                <geometry>
                    <mesh>
                        <scale>0.001 0.001 0.001</scale>
                        <uri>file:///src/altair_simulation/meshes/rl4.stl</uri>
                    </mesh>
                </geometry>
                <material>
                    <diffuse>0.75000006 0.75000006 0.75000006 1</diffuse>
                    <ambient>0.75000006 0.75000006 0.75000006 1</ambient>
                </material>
            </visual>
            <self_collide>false</self_collide>
            <enable_wind>false</enable_wind>
        </link>
        <joint name='r_ank_pitch' type='revolute'>
            <pose>0 0 0 0 0 0</pose>
            <parent>r_knee_link</parent>
            <child>r_ank_pitch_link</child>
            <axis>
                <xyz>0 1 0</xyz>
                <limit>
                    <lower>-2.8274333882308138</lower>
                    <upper>2.8274333882308138</upper>
                    <effort>1000</effort>
                    <velocity>100</velocity>
                    <stiffness>100000000</stiffness>
                    <dissipation>1</dissipation>
                </limit>
                <dynamics>
                    <spring_reference>0</spring_reference>
                    <spring_stiffness>0</spring_stiffness>
                    <damping>0.10000000000000001</damping>
                    <friction>0</friction>
                </dynamics>
            </axis>
        </joint>
        <link name='r_ank_pitch_link'>
            <pose>9.9999999999988987e-05 -0.054000000000000006 -0.24865000000000004 0 0 0</pose>
            <inertial>
                <pose>-0.020219999999999998 0.018720000000000001 0.01214 0 0 0</pose>
                <mass>0.17885999999999999</mass>
                <inertia>
                    <ixx>4.6610000000000003e-05</ixx>
                    <ixy>1.0100000000000001e-06</ixy>
                    <ixz>1.31e-06</ixz>
                    <iyy>0.00012522999999999999</iyy>
                    <iyz>-5.9999999999999995e-08</iyz>
                    <izz>0.00010857</izz>
                </inertia>
            </inertial>
            <collision name='r_ank_pitch_link_collision'>
                <pose>0 0 0 0 0 0</pose>
                <geometry>
                    <mesh>
                        <scale>0.001 0.001 0.001</scale>
                        <uri>file:///src/altair_simulation/meshes/rl5.stl</uri>
                    </mesh>
                </geometry>
                <surface>
                    <contact>
                        <ode />
                    </contact>
                    <friction>
                        <ode>
                            <mu>0.20000000000000001</mu>
                            <mu2>0.20000000000000001</mu2>
                        </ode>
                    </friction>
                </surface>
            </collision>
            <visual name='r_ank_pitch_link_visual'>
                <pose>0 0 0 0 0 0</pose>
                <geometry>
                    <mesh>
                        <scale>0.001 0.001 0.001</scale>
                        <uri>file:///src/altair_simulation/meshes/rl5.stl</uri>
                    </mesh>
                </geometry>
                <material>
                    <diffuse>0.75000006 0.75000006 0.75000006 1</diffuse>
                    <ambient>0.75000006 0.75000006 0.75000006 1</ambient>
                </material>
            </visual>
            <self_collide>false</self_collide>
            <enable_wind>false</enable_wind>
        </link>
        <joint name='r_ank_roll' type='revolute'>
            <pose>0 0 0 0 0 0</pose>
            <parent>r_ank_pitch_link</parent>
            <child>r_ank_roll_link</child>
            <axis>
                <xyz>1 0 0</xyz>
                <limit>
                    <lower>-2.8274333882308138</lower>
                    <upper>2.8274333882308138</upper>
                    <effort>1000</effort>
                    <velocity>100</velocity>
                    <stiffness>100000000</stiffness>
                    <dissipation>1</dissipation>
                </limit>
                <dynamics>
                    <spring_reference>0</spring_reference>
                    <spring_stiffness>0</spring_stiffness>
                    <damping>0.10000000000000001</damping>
                    <friction>0</friction>
                </dynamics>
            </axis>
        </joint>
        <link name='r_ank_roll_link'>
            <pose>-0.024000000000000021 -0.035000000000000003 -0.24865000000000004 0 0 0</pose>
            <inertial>
                <pose>0.023730000000000001 -0.010370000000000001 -0.0276 0 0 0</pose>
                <mass>0.069339999999999999</mass>
                <inertia>
                    <ixx>4.0339999999999997e-05</ixx>
                    <ixy>1.9000000000000001e-07</ixy>
                    <ixz>1.1999999999999999e-07</ixz>
                    <iyy>7.8739999999999995e-05</iyy>
                    <iyz>-1.0100000000000001e-06</iyz>
                    <izz>0.00011579</izz>
                </inertia>
            </inertial>
            <collision name='r_ank_roll_link_collision'>
                <pose>0 0 0 0 0 0</pose>
                <geometry>
                    <mesh>
                        <scale>0.001 0.001 0.001</scale>
                        <uri>file:///src/altair_simulation/meshes/rl6.stl</uri>
                    </mesh>
                </geometry>
                <surface>
                    <contact>
                        <ode>
                            <kp>100000</kp>
                            <kd>100</kd>
                            <max_vel>1</max_vel>
                            <min_depth>0.001</min_depth>
                        </ode>
                    </contact>
                    <friction>
                        <ode>
                            <mu>1.5</mu>
                            <mu2>1.5</mu2>
                            <fdir1>1 0 0</fdir1>
                        </ode>
                    </friction>
                </surface>
            </collision>
            <visual name='r_ank_roll_link_visual'>
                <pose>0 0 0 0 0 0</pose>
                <geometry>
                    <mesh>
                        <scale>0.001 0.001 0.001</scale>
                        <uri>file:///src/altair_simulation/meshes/rl6.stl</uri>
                    </mesh>
                </geometry>
                <material>
                    <diffuse>0.75000006 0.75000006 0.75000006 1</diffuse>
                    <ambient>0.75000006 0.75000006 0.75000006 1</ambient>
                </material>
            </visual>
            <enable_wind>false</enable_wind>
        </link>
        <joint name='r_sho_pitch' type='revolute'>
            <pose>0 0 0 0 0 0</pose>
            <parent>base</parent>
            <child>r_sho_pitch_link</child>
            <axis>
                <xyz>0 -1 0</xyz>
                <limit>
                    <lower>-2.8274333882308138</lower>
                    <upper>2.8274333882308138</upper>
                    <effort>1000</effort>
                    <velocity>100</velocity>
                    <stiffness>100000000</stiffness>
                    <dissipation>1</dissipation>
                </limit>
                <dynamics>
                    <spring_reference>0</spring_reference>
                    <spring_stiffness>0</spring_stiffness>
                    <damping>0.10000000000000001</damping>
                    <friction>0</friction>
                </dynamics>
            </axis>
        </joint>
        <link name='r_sho_pitch_link'>
            <pose>-0.00099999999999988987 -0.059999999999999998 0.11099999999999999 0 0 0</pose>
            <inertial>
                <pose>0 -0.0082299999999999995 -0.00233 0 0 0</pose>
                <mass>0.01176</mass>
                <inertia>
                    <ixx>1.6500000000000001e-06</ixx>
                    <ixy>0</ixy>
                    <ixz>0</ixz>
                    <iyy>3.8700000000000002e-06</iyy>
                    <iyz>-3.1e-07</iyz>
                    <izz>3.9700000000000001e-06</izz>
                </inertia>
            </inertial>
            <collision name='r_sho_pitch_link_collision'>
                <pose>0 0 0 0 0 0</pose>
                <geometry>
                    <mesh>
                        <scale>0.001 0.001 0.001</scale>
                        <uri>file:///src/altair_simulation/meshes/ra1.stl</uri>
                    </mesh>
                </geometry>
                <surface>
                    <contact>
                        <ode />
                    </contact>
                    <friction>
                        <ode>
                            <mu>0.20000000000000001</mu>
                            <mu2>0.20000000000000001</mu2>
                        </ode>
                    </friction>
                </surface>
            </collision>
            <visual name='r_sho_pitch_link_visual'>
                <pose>0 0 0 0 0 0</pose>
                <geometry>
                    <mesh>
                        <scale>0.001 0.001 0.001</scale>
                        <uri>file:///src/altair_simulation/meshes/ra1.stl</uri>
                    </mesh>
                </geometry>
                <material>
                    <diffuse>0.75000006 0.75000006 0.75000006 1</diffuse>
                    <ambient>0.75000006 0.75000006 0.75000006 1</ambient>
                </material>
            </visual>
            <self_collide>false</self_collide>
            <enable_wind>false</enable_wind>
        </link>
        <joint name='r_sho_roll' type='revolute'>
            <pose>0 0 0 0 0 0</pose>
            <parent>r_sho_pitch_link</parent>
            <child>r_sho_roll_link</child>
            <axis>
                <xyz>-1 0 0</xyz>
                <limit>
                    <lower>-2.8274333882308138</lower>
                    <upper>2.8274333882308138</upper>
                    <effort>1000</effort>
                    <velocity>100</velocity>
                    <stiffness>100000000</stiffness>
                    <dissipation>1</dissipation>
                </limit>
                <dynamics>
                    <spring_reference>0</spring_reference>
                    <spring_stiffness>0</spring_stiffness>
                    <damping>0.10000000000000001</damping>
                    <friction>0</friction>
                </dynamics>
            </axis>
        </joint>
        <link name='r_sho_roll_link'>
            <pose>0.018000000000000016 -0.088499999999999995 0.10099999999999998 0 0 0</pose>
            <inertial>
                <pose>-0.018440000000000002 -0.04514 0.00027999999999999998 0 0 0</pose>
                <mass>0.17757999999999999</mass>
                <inertia>
                    <ixx>0.00022803999999999999</ixx>
                    <ixy>1e-08</ixy>
                    <ixz>2.9999999999999997e-08</ixz>
                    <iyy>3.042e-05</iyy>
                    <iyz>-5.8999999999999996e-07</iyz>
                    <izz>0.00023473999999999999</izz>
                </inertia>
            </inertial>
            <collision name='r_sho_roll_link_collision'>
                <pose>0 0 0 0 0 0</pose>
                <geometry>
                    <mesh>
                        <scale>0.001 0.001 0.001</scale>
                        <uri>file:///src/altair_simulation/meshes/ra2.stl</uri>
                    </mesh>
                </geometry>
                <surface>
                    <contact>
                        <ode />
                    </contact>
                    <friction>
                        <ode>
                            <mu>0.20000000000000001</mu>
                            <mu2>0.20000000000000001</mu2>
                        </ode>
                    </friction>
                </surface>
            </collision>
            <visual name='r_sho_roll_link_visual'>
                <pose>0 0 0 0 0 0</pose>
                <geometry>
                    <mesh>
                        <scale>0.001 0.001 0.001</scale>
                        <uri>file:///src/altair_simulation/meshes/ra2.stl</uri>
                    </mesh>
                </geometry>
                <material>
                    <diffuse>0.75000006 0.75000006 0.75000006 1</diffuse>
                    <ambient>0.75000006 0.75000006 0.75000006 1</ambient>
                </material>
            </visual>
            <self_collide>false</self_collide>
            <enable_wind>false</enable_wind>
        </link>
        <joint name='r_el' type='revolute'>
            <pose>0 0 0 0 0 0</pose>
            <parent>r_sho_roll_link</parent>
            <child>r_el_link</child>
            <axis>
                <xyz>1 0 0</xyz>
                <limit>
                    <lower>-2.8274333882308138</lower>
                    <upper>2.8274333882308138</upper>
                    <effort>1000</effort>
                    <velocity>100</velocity>
                    <stiffness>100000000</stiffness>
                    <dissipation>1</dissipation>
                </limit>
                <dynamics>
                    <spring_reference>0</spring_reference>
                    <spring_stiffness>0</spring_stiffness>
                    <damping>0.10000000000000001</damping>
                    <friction>0</friction>
                </dynamics>
            </axis>
        </joint>
        <link name='r_el_link'>
            <pose>0.018000000000000016 -0.1789 0.10089999999999999 0 0 0</pose>
            <inertial>
                <pose>-0.019 -0.070330000000000004 0.0038 0 0 0</pose>
                <mass>0.041270000000000001</mass>
                <inertia>
                    <ixx>6.1959999999999996e-05</ixx>
                    <ixy>0</ixy>
                    <ixz>0</ixz>
                    <iyy>1.2310000000000001e-05</iyy>
                    <iyz>3.72e-06</iyz>
                    <izz>6.8540000000000004e-05</izz>
                </inertia>
            </inertial>
            <collision name='r_el_link_collision'>
                <pose>0 0 0 0 0 0</pose>
                <geometry>
                    <mesh>
                        <scale>0.001 0.001 0.001</scale>
                        <uri>file:///src/altair_simulation/meshes/ra3.stl</uri>
                    </mesh>
                </geometry>
                <surface>
                    <contact>
                        <ode />
                    </contact>
                    <friction>
                        <ode>
                            <mu>0.20000000000000001</mu>
                            <mu2>0.20000000000000001</mu2>
                        </ode>
                    </friction>
                </surface>
            </collision>
            <visual name='r_el_link_visual'>
                <pose>0 0 0 0 0 0</pose>
                <geometry>
                    <mesh>
                        <scale>0.001 0.001 0.001</scale>
                        <uri>file:///src/altair_simulation/meshes/ra3.stl</uri>
                    </mesh>
                </geometry>
                <material>
                    <diffuse>0.75000006 0.75000006 0.75000006 1</diffuse>
                    <ambient>0.75000006 0.75000006 0.75000006 1</ambient>
                </material>
            </visual>
            <self_collide>false</self_collide>
            <enable_wind>false</enable_wind>
        </link>
        <frame name='imu_fixed' attached_to='body_link'>
            <pose>0 0 0 0 0 0</pose>
        </frame>
        <frame name='imu_link' attached_to='imu_fixed'>
            <pose>0 0 0 0 0 0</pose>
        </frame>
        <frame name='base_fixed' attached_to='base'>
            <pose>0 0 0 0 0 0</pose>
        </frame>
        <frame name='body_link' attached_to='base_fixed'>
            <pose>0 0 0 0 0 0</pose>
        </frame>
        <frame name='cam' attached_to='head_tilt_link'>
            <pose>0.014250000000000001 -0.019 0.049750000000000003 -1.5707963267948959
                -5.5511151231257827e-17 -1.5707963267948959</pose>
        </frame>
        <frame name='cam_link' attached_to='cam'>
            <pose>0 0 0 0 0 0</pose>
        </frame>
        <frame name='cam_gazebo' attached_to='head_tilt_link'>
            <pose>0.014250000000000001 -0.019 0.049750000000000003 0 0 0</pose>
        </frame>
        <frame name='cam_gazebo_link' attached_to='cam_gazebo'>
            <pose>0 0 0 0 0 0</pose>
        </frame>
        <pose>-1.0974200963973999 0 0.28999999165534973 0 0 0</pose>
        <static>false</static>
        <self_collide>false</self_collide>
    </model>
</sdf>